Traceback (most recent call last):
  File "/usr/share/miniconda/envs/test/lib/python3.11/site-packages/jupyter_cache/executors/utils.py", line 58, in single_nb_execution
    executenb(
  File "/usr/share/miniconda/envs/test/lib/python3.11/site-packages/nbclient/client.py", line 1314, in execute
    return NotebookClient(nb=nb, resources=resources, km=km, **kwargs).execute()
           ^^^^^^^^^^^^^^^^^^^^^^^^^^^^^^^^^^^^^^^^^^^^^^^^^^^^^^^^^^^^^^^^^^^^^
  File "/usr/share/miniconda/envs/test/lib/python3.11/site-packages/jupyter_core/utils/__init__.py", line 165, in wrapped
    return loop.run_until_complete(inner)
           ^^^^^^^^^^^^^^^^^^^^^^^^^^^^^^
  File "/usr/share/miniconda/envs/test/lib/python3.11/asyncio/base_events.py", line 654, in run_until_complete
    return future.result()
           ^^^^^^^^^^^^^^^
  File "/usr/share/miniconda/envs/test/lib/python3.11/site-packages/nbclient/client.py", line 709, in async_execute
    await self.async_execute_cell(
  File "/usr/share/miniconda/envs/test/lib/python3.11/site-packages/nbclient/client.py", line 1062, in async_execute_cell
    await self._check_raise_for_error(cell, cell_index, exec_reply)
  File "/usr/share/miniconda/envs/test/lib/python3.11/site-packages/nbclient/client.py", line 918, in _check_raise_for_error
    raise CellExecutionError.from_cell_and_msg(cell, exec_reply_content)
nbclient.exceptions.CellExecutionError: An error occurred while executing the following cell:
------------------
import osmnx as ox
import pandas as pd
import matplotlib.pyplot as plt

import json

from nrel.routee.compass.io import generate_compass_dataset
from nrel.routee.compass import CompassApp

# Try importing required packages to fail sooner if absent
try:
    import rasterio
    from osgeo import gdal
except:
    raise ImportError("Not all dependencies are installed")
------------------


[0;31m---------------------------------------------------------------------------[0m
[0;31mImportError[0m                               Traceback (most recent call last)
Cell [0;32mIn[1], line 12[0m
[1;32m     11[0m [38;5;28;01mtry[39;00m:
[0;32m---> 12[0m     [38;5;28;01mimport[39;00m [38;5;21;01mrasterio[39;00m
[1;32m     13[0m     [38;5;28;01mfrom[39;00m [38;5;21;01mosgeo[39;00m [38;5;28;01mimport[39;00m gdal

File [0;32m/usr/share/miniconda/envs/test/lib/python3.11/site-packages/rasterio/__init__.py:28[0m
[1;32m     27[0m [38;5;28;01mfrom[39;00m [38;5;21;01mrasterio[39;00m[38;5;21;01m.[39;00m[38;5;21;01m_show_versions[39;00m [38;5;28;01mimport[39;00m show_versions
[0;32m---> 28[0m [38;5;28;01mfrom[39;00m [38;5;21;01mrasterio[39;00m[38;5;21;01m.[39;00m[38;5;21;01m_version[39;00m [38;5;28;01mimport[39;00m gdal_version, get_geos_version, get_proj_version
[1;32m     29[0m [38;5;28;01mfrom[39;00m [38;5;21;01mrasterio[39;00m[38;5;21;01m.[39;00m[38;5;21;01mcrs[39;00m [38;5;28;01mimport[39;00m CRS

[0;31mImportError[0m: libpoppler.so.126: cannot open shared object file: No such file or directory

During handling of the above exception, another exception occurred:

[0;31mImportError[0m                               Traceback (most recent call last)
Cell [0;32mIn[1], line 15[0m
[1;32m     13[0m     [38;5;28;01mfrom[39;00m [38;5;21;01mosgeo[39;00m [38;5;28;01mimport[39;00m gdal
[1;32m     14[0m [38;5;28;01mexcept[39;00m:
[0;32m---> 15[0m     [38;5;28;01mraise[39;00m [38;5;167;01mImportError[39;00m([38;5;124m"[39m[38;5;124mNot all dependencies are installed[39m[38;5;124m"[39m)

[0;31mImportError[0m: Not all dependencies are installed

