Traceback (most recent call last):
  File "/usr/share/miniconda/envs/test/lib/python3.11/site-packages/jupyter_core/utils/__init__.py", line 154, in wrapped
    asyncio.get_running_loop()
RuntimeError: no running event loop

During handling of the above exception, another exception occurred:

Traceback (most recent call last):
  File "/usr/share/miniconda/envs/test/lib/python3.11/site-packages/jupyter_cache/executors/utils.py", line 58, in single_nb_execution
    executenb(
  File "/usr/share/miniconda/envs/test/lib/python3.11/site-packages/nbclient/client.py", line 1319, in execute
    return NotebookClient(nb=nb, resources=resources, km=km, **kwargs).execute()
           ^^^^^^^^^^^^^^^^^^^^^^^^^^^^^^^^^^^^^^^^^^^^^^^^^^^^^^^^^^^^^^^^^^^^^
  File "/usr/share/miniconda/envs/test/lib/python3.11/site-packages/jupyter_core/utils/__init__.py", line 158, in wrapped
    return loop.run_until_complete(inner)
           ^^^^^^^^^^^^^^^^^^^^^^^^^^^^^^
  File "/usr/share/miniconda/envs/test/lib/python3.11/asyncio/base_events.py", line 654, in run_until_complete
    return future.result()
           ^^^^^^^^^^^^^^^
  File "/usr/share/miniconda/envs/test/lib/python3.11/site-packages/nbclient/client.py", line 709, in async_execute
    await self.async_execute_cell(
  File "/usr/share/miniconda/envs/test/lib/python3.11/site-packages/nbclient/client.py", line 1062, in async_execute_cell
    await self._check_raise_for_error(cell, cell_index, exec_reply)
  File "/usr/share/miniconda/envs/test/lib/python3.11/site-packages/nbclient/client.py", line 918, in _check_raise_for_error
    raise CellExecutionError.from_cell_and_msg(cell, exec_reply_content)
nbclient.exceptions.CellExecutionError: An error occurred while executing the following cell:
------------------

generate_compass_dataset(g, output_directory="denver_co")



------------------

----- stderr -----
INFO:nrel.routee.compass.io.generate_dataset:running pipeline import with phases: [['GRAPH', 'GRADE', 'CONFIG', 'POWERTRAIN', 'CHARGING_STATIONS']]
----- stderr -----
INFO:nrel.routee.compass.io.generate_dataset:processing graph topology and speeds
----- stderr -----
INFO:nrel.routee.compass.io.generate_dataset:adding grade information
----- stderr -----
INFO:nrel.routee.compass.io.utils:downloading n40w106
----- stderr -----
INFO:nrel.routee.compass.io.utils:downloading n40w105
----- stderr -----
INFO:nrel.routee.compass.io.generate_dataset:processing vertices
----- stderr -----
INFO:nrel.routee.compass.io.generate_dataset:processing edges
----- stderr -----
INFO:nrel.routee.compass.io.generate_dataset:writing vertex files
----- stderr -----
INFO:nrel.routee.compass.io.generate_dataset:writing edge files
----- stderr -----
INFO:nrel.routee.compass.io.generate_dataset:writing edge attribute files
----- stderr -----
INFO:nrel.routee.compass.io.generate_dataset:copying default configuration TOML files
------------------

[31m---------------------------------------------------------------------------[39m
[31mNonExistentKey[39m                            Traceback (most recent call last)
[36mCell[39m[36m [39m[32mIn[3][39m[32m, line 1[39m
[32m----> [39m[32m1[39m [43mgenerate_compass_dataset[49m[43m([49m[43mg[49m[43m,[49m[43m [49m[43moutput_directory[49m[43m=[49m[33;43m"[39;49m[33;43mdenver_co[39;49m[33;43m"[39;49m[43m)[49m

[36mFile [39m[32m/usr/share/miniconda/envs/test/lib/python3.11/site-packages/nrel/routee/compass/io/generate_dataset.py:228[39m, in [36mgenerate_compass_dataset[39m[34m(g, output_directory, hwy_speeds, fallback, agg, phases, raster_resolution_arc_seconds, default_config, requests_kwds, afdc_api_key)[39m
[32m    226[39m     [38;5;28;01mif[39;00m filename == [33m"[39m[33mosm_default_energy.toml[39m[33m"[39m:
[32m    227[39m         [38;5;28;01mif[39;00m GeneratePipelinePhase.GRADE [38;5;129;01min[39;00m phases:
[32m--> [39m[32m228[39m             [43minit_toml[49m[43m[[49m[33;43m"[39;49m[33;43mtraversal[39;49m[33;43m"[39;49m[43m][49m[[33m"[39m[33mgrade_table_input_file[39m[33m"[39m] = (
[32m    229[39m                 [33m"[39m[33medges-grade-enumerated.txt.gz[39m[33m"[39m
[32m    230[39m             )
[32m    231[39m             init_toml[[33m"[39m[33mtraversal[39m[33m"[39m][[33m"[39m[33mgrade_table_grade_unit[39m[33m"[39m] = [33m"[39m[33mdecimal[39m[33m"[39m
[32m    232[39m [38;5;28;01mwith[39;00m [38;5;28mopen[39m(output_directory / filename, [33m"[39m[33mw[39m[33m"[39m) [38;5;28;01mas[39;00m f:

[36mFile [39m[32m/usr/share/miniconda/envs/test/lib/python3.11/site-packages/tomlkit/container.py:652[39m, in [36mContainer.__getitem__[39m[34m(self, key)[39m
[32m    651[39m [38;5;28;01mdef[39;00m[38;5;250m [39m[34m__getitem__[39m([38;5;28mself[39m, key: Key | [38;5;28mstr[39m) -> Item | Container:
[32m--> [39m[32m652[39m     item = [38;5;28;43mself[39;49m[43m.[49m[43mitem[49m[43m([49m[43mkey[49m[43m)[49m
[32m    653[39m     [38;5;28;01mif[39;00m [38;5;28misinstance[39m(item, Item) [38;5;129;01mand[39;00m item.is_boolean():
[32m    654[39m         [38;5;28;01mreturn[39;00m item.value

[36mFile [39m[32m/usr/share/miniconda/envs/test/lib/python3.11/site-packages/tomlkit/container.py:470[39m, in [36mContainer.item[39m[34m(self, key)[39m
[32m    468[39m idx = [38;5;28mself[39m._map.get(key)
[32m    469[39m [38;5;28;01mif[39;00m idx [38;5;129;01mis[39;00m [38;5;28;01mNone[39;00m:
[32m--> [39m[32m470[39m     [38;5;28;01mraise[39;00m NonExistentKey(key)
[32m    472[39m [38;5;28;01mif[39;00m [38;5;28misinstance[39m(idx, [38;5;28mtuple[39m):
[32m    473[39m     [38;5;66;03m# The item we are getting is an out of order table[39;00m
[32m    474[39m     [38;5;66;03m# so we need a proxy to retrieve the proper objects[39;00m
[32m    475[39m     [38;5;66;03m# from the parent container[39;00m
[32m    476[39m     [38;5;28;01mreturn[39;00m OutOfOrderTableProxy([38;5;28mself[39m, idx)

[31mNonExistentKey[39m: 'Key "traversal" does not exist.'

