Traceback (most recent call last):
  File "/usr/share/miniconda/envs/test/lib/python3.11/site-packages/jupyter_core/utils/__init__.py", line 154, in wrapped
    asyncio.get_running_loop()
RuntimeError: no running event loop

During handling of the above exception, another exception occurred:

Traceback (most recent call last):
  File "/usr/share/miniconda/envs/test/lib/python3.11/site-packages/jupyter_cache/executors/utils.py", line 58, in single_nb_execution
    executenb(
  File "/usr/share/miniconda/envs/test/lib/python3.11/site-packages/nbclient/client.py", line 1319, in execute
    return NotebookClient(nb=nb, resources=resources, km=km, **kwargs).execute()
           ^^^^^^^^^^^^^^^^^^^^^^^^^^^^^^^^^^^^^^^^^^^^^^^^^^^^^^^^^^^^^^^^^^^^^
  File "/usr/share/miniconda/envs/test/lib/python3.11/site-packages/jupyter_core/utils/__init__.py", line 158, in wrapped
    return loop.run_until_complete(inner)
           ^^^^^^^^^^^^^^^^^^^^^^^^^^^^^^
  File "/usr/share/miniconda/envs/test/lib/python3.11/asyncio/base_events.py", line 654, in run_until_complete
    return future.result()
           ^^^^^^^^^^^^^^^
  File "/usr/share/miniconda/envs/test/lib/python3.11/site-packages/nbclient/client.py", line 709, in async_execute
    await self.async_execute_cell(
  File "/usr/share/miniconda/envs/test/lib/python3.11/site-packages/nbclient/client.py", line 1062, in async_execute_cell
    await self._check_raise_for_error(cell, cell_index, exec_reply)
  File "/usr/share/miniconda/envs/test/lib/python3.11/site-packages/nbclient/client.py", line 918, in _check_raise_for_error
    raise CellExecutionError.from_cell_and_msg(cell, exec_reply_content)
nbclient.exceptions.CellExecutionError: An error occurred while executing the following cell:
------------------

app = CompassApp.from_config_file("./denver_co/osm_default_charging.toml")

------------------


[31m---------------------------------------------------------------------------[39m
[31mException[39m                                 Traceback (most recent call last)
[36mCell[39m[36m [39m[32mIn[2][39m[32m, line 1[39m
[32m----> [39m[32m1[39m app = [43mCompassApp[49m[43m.[49m[43mfrom_config_file[49m[43m([49m[33;43m"[39;49m[33;43m./denver_co/osm_default_charging.toml[39;49m[33;43m"[39;49m[43m)[49m

[36mFile [39m[32m/usr/share/miniconda/envs/test/lib/python3.11/site-packages/nrel/routee/compass/compass_app.py:79[39m, in [36mCompassApp.from_config_file[39m[34m(cls, config_file)[39m
[32m     76[39m [38;5;28;01mwith[39;00m [38;5;28mopen[39m(config_path) [38;5;28;01mas[39;00m f:
[32m     77[39m     toml_config = tomlkit.load(f)
[32m---> [39m[32m79[39m [38;5;28;01mreturn[39;00m [38;5;28;43mcls[39;49m[43m.[49m[43mfrom_dict[49m[43m([49m[43mtoml_config[49m[43m,[49m[43m [49m[43mconfig_path[49m[43m)[49m

[36mFile [39m[32m/usr/share/miniconda/envs/test/lib/python3.11/site-packages/nrel/routee/compass/compass_app.py:102[39m, in [36mCompassApp.from_dict[39m[34m(cls, config, working_dir)[39m
[32m    100[39m path_str = [38;5;28mstr[39m(working_dir.absolute()) [38;5;28;01mif[39;00m working_dir [38;5;129;01mis[39;00m [38;5;129;01mnot[39;00m [38;5;28;01mNone[39;00m [38;5;28;01melse[39;00m [33m"[39m[33m"[39m
[32m    101[39m toml_string = tomlkit.dumps(config)
[32m--> [39m[32m102[39m app = [38;5;28;43mcls[39;49m[43m.[49m[43mget_constructor[49m[43m([49m[43m)[49m[43m.[49m[43m_from_config_toml_string[49m[43m([49m[43mtoml_string[49m[43m,[49m[43m [49m[43mpath_str[49m[43m)[49m
[32m    103[39m [38;5;28;01mreturn[39;00m [38;5;28mcls[39m(app, config)

[31mException[39m: Error while creating CompassApp from config toml string: 
        Could not find incoming configuration file 'charging-stations.csv.gz' for key 'charging_station_input_file'

        Tried: 
         - 'charging-stations.csv.gz'
         - '/home/runner/work/routee-compass/routee-compass/docs/examples/denver_co/charging-stations.csv.gz'
        

